Workbook

Sheet Q3.1 Slotting Design
A1: Q3.1 - SLOTTING DESIGN (ABC velocity-based)
A2: Velocity decides the storage zone. Inputs per prompt: velocity, pick rate, size. U-shaped warehouse: receiving and packing on the same front side, creating a golden pick-face next to packing.
A4: A. MODEL ASSUMPTIONS (blue = editable input)
A5: Walk speed (m/min) | B5: 72 | C5: 1.2 m/s standard
A6: Round-trip factor | B6: 2 | C6: pick location to packing and back
A7: Dist: A Pick-face to packing (m) | B7: 8 | C7: golden zone, nearest
A8: Dist: B Intermediate to packing (m) | B8: 25 | C8: mid bay
A9: Dist: C Reserve to packing (m) | B9: 47.5 | C9: back / upper rack
A10: Pick rate A (pcs/min) | B10: 4 | C10: fast pick-face
A11: Pick rate B (pcs/min) | B11: 2.5 | C11: carton-centric
A12: Pick rate C (pcs/min) | B12: 2 | C12: slow reserve
A14: B. ZONE DESIGN — VELOCITY chooses the zone
A15: Zone | B15: Class | C15: # SKU | D15: Total picks (order freq) | E15: Pick mode | F15: Slot rule | G15: Dist to packing (m)
A16: A - Pick-face | B16: Class A / Fast | C16: 28 | D16: 5767 | E16: Loose + carton break-bulk | F16: Highest order frequency -> nearest slots, golden zone next to packing. | G16: 8
A17: B - Intermediate | B17: Class B | C17: 39 | D17: 7945 | E17: Carton picking + replenish A | F17: Medium velocity -> mid bay; min/max feeds the A pick-face. | G17: 25
A18: C - Reserve | B18: Class C / Slow | C18: 403 | D18: 7082 | E18: Pallet store, pick on demand | F18: Low velocity per SKU -> far / upper rack, bulk. Rarely picked so distance is acceptable. | G18: 47.5
A20: Note: zone is determined by VELOCITY (pick frequency) only. Within a zone, slot order follows velocity then size (cube). No shelf-height / weight-band rule is applied.

Sheet Q3.1 Travel Proof
A1: Q3.1 - TRAVEL-TIME PROOF (>= 30% reduction)
A2: Image formula: Total distance traveled = SUM_i SUM_j ( Tij * Dij ). Flow = packing(P) <-> each zone, so Tij=picks_j, Dij=zone dist. Avg distance/pick = Total dist / total picks.
A4: A. TOTAL DISTANCE BY ZONE (Tij x Dij x round-trip)
A5: Zone (j) | B5: Picks Tij (velocity) | C5: Dist Dij (m) | D5: Round-trip distance = Tij*Dij*2 (m)
A6: Zone A | B6: 5767 | C6: ='Q3.1 Slotting Design'!$B$7 -> 8 | D6: =B6*C6*'Q3.1 Slotting Design'!$B$6 -> 92272
A7: Zone B | B7: 7945 | C7: ='Q3.1 Slotting Design'!$B$8 -> 25 | D7: =B7*C7*'Q3.1 Slotting Design'!$B$6 -> 397250
A8: Zone C | B8: 7082 | C8: ='Q3.1 Slotting Design'!$B$9 -> 47.5 | D8: =B8*C8*'Q3.1 Slotting Design'!$B$6 -> 672790
A9: TOTAL | B9: =SUM(B6:B8) -> 20794 | D9: =SUM(D6:D8) -> 1162312
A11: B. RESULTS
A12: Total picks | B12: =B9 -> 20794
A13: OPTIMIZED total round-trip distance (m) | B13: =D9 -> 1162312
A14: OPTIMIZED avg distance per pick (one-way, m) | B14: =D9/(B9*2) -> 27.948254
A15: OPTIMIZED travel time (min) | B15: =D9/'Q3.1 Slotting Design'!$B$5 -> 16143.222
A16: BASELINE random avg distance (one-way, m) | B16: =(28*8+39*25+403*47.5)/470 -> 43.279787
A17: BASELINE total round-trip distance (m) | B17: =B16*B9*'Q3.1 Slotting Design'!$B$6 -> 1799919.8
A18: BASELINE travel time (min) | B18: =B17/'Q3.1 Slotting Design'!$B$5 -> 24998.886
A19: TRAVEL-TIME REDUCTION | B19: =1-B15/B18 -> 0.35424234
A20: Target | B20: =0.3 -> 0.3
A22: Derivation: the image formula gives TOTAL distance. Dividing by total picks yields the AVERAGE distance per pick. Baseline uses the SKU-count-weighted mean distance (random placement = every pick travels the warehouse average, 43.3 m). Optimized concentrates the high-frequency Zone-A picks at 8 m, cutting the average to 28.0 m.

Sheet Q3.1 Slot Assignment
A1: Q3.1 - SLOT ASSIGNMENT (all 470 SKUs)
A2: velocity = order frequency / pick rate (picking-time load, min). Sorted by velocity within zone. pick rate (pcs/min) and size (unit cube, L/pcs) shown as required inputs.
A4: Slot ID | B4: SKU | C4: Product | D4: Cat | E4: Zone | F4: Order freq | G4: Pick rate (pcs/min) | H4: Velocity (freq/rate) | I4: Size (L/pcs) | J4: Avg order qty | K4: Dist (m)
A5: A-001 | B5: 4200008229 | C5: Quạt treo ASIAvina - VY377990 - | D5: Fan | E5: A | F5: 825 | G5: 4 | H5: =F5/G5 -> 206.25 | I5: 41.4 | J5: 6.8 | K5: 8
A6: A-002 | B6: 4200008371 | C6: QUẠT ĐỨNG VY619990 | D6: Fan | E6: A | F6: 682 | G6: 4 | H6: =F6/G6 -> 170.5 | I6: 67.5 | J6: 4.9 | K6: 8
A7: A-003 | B7: 4200008366 | C7: QUẠT SÀN TURB0 VY616790 | D7: Fan | E7: A | F7: 680 | G7: 4 | H7: =F7/G7 -> 170 | I7: 104.5 | J7: 4.2 | K7: 8
A8: A-004 | B8: 4200008117 | C8: Quạt treo ASIAvina - VY357690 - | D8: Fan | E8: A | F8: 666 | G8: 4 | H8: =F8/G8 -> 166.5 | I8: 41.4 | J8: 6 | K8: 8
A9: A-005 | B9: 4200008102 | C9: Quạt lửng ASIAvina - VY538790 - | D9: Fan | E9: A | F9: 514 | G9: 4 | H9: =F9/G9 -> 128.5 | I9: 50.8 | J9: 24.7 | K9: 8
A10: A-006 | B10: 4200009163 | C10: Quạt lửng ASIAVINA - VY628890 - | D10: Fan | E10: A | F10: 267 | G10: 4 | H10: =F10/G10 -> 66.75 | I10: 67.5 | J10: 202.1 | K10: 8
A11: A-007 | B11: 4200007858 | C11: Quạt sàn ASIAvina - VY636790 - X | D11: Fan | E11: A | F11: 210 | G11: 4 | H11: =F11/G11 -> 52.5 | I11: 102.6 | J11: 35.4 | K11: 8
A12: A-008 | B12: 4200008999 | C12: Quạt đứng ASIAVINA Turbo X - VY6 | D12: Fan | E12: A | F12: 170 | G12: 4 | H12: =F12/G12 -> 42.5 | I12: 46.8 | J12: 54.6 | K12: 8
A13: A-009 | B13: 4200000163 | C13: Quạt trần đảo ASIAvina - X16001- | D13: Fan | E13: A | F13: 161 | G13: 4 | H13: =F13/G13 -> 40.25 | I13: 55 | J13: 66.2 | K13: 8
A14: A-010 | B14: 4200009000 | C14: Quạt đứng ASIAVINA Turbo X - VY6 | D14: Fan | E14: A | F14: 150 | G14: 4 | H14: =F14/G14 -> 37.5 | I14: 46.7 | J14: 89 | K14: 8
A15: A-011 | B15: 4200009001 | C15: Quạt treo ASIAVINA Turbo X - VY6 | D15: Fan | E15: A | F15: 147 | G15: 4 | H15: =F15/G15 -> 36.75 | I15: 37.5 | J15: 36.3 | K15: 8
A16: A-012 | B16: 4200008101 | C16: Quạt lửng ASIAvina - VY538990 - | D16: Fan | E16: A | F16: 131 | G16: 4 | H16: =F16/G16 -> 32.75 | I16: 47.6 | J16: 52.3 | K16: 8
... A31: A-027 | B31: 4100000738 | C31: Quạt đứng - TEFAL - VF4420F2 - đ | D31: Fan | E31: A | F31: 5 | G31: 4 | H31: =F31/G31 -> 1.25 | I31: 58.2 | J31: 624 | K31: 8
A32: A-028 | B32: 4100000838 | E32: A | F32: 4 | G32: 4 | H32: =F32/G32 -> 1 | I32: 49.1 | J32: 550.4 | K32: 8
A33: B-001 | B33: 7211005095 | C33: Nồi cơm điện tử Tefal Rice Mate | D33: SDA | E33: B | F33: 613 | G33: 2.5 | H33: =F33/G33 -> 245.2 | I33: 31 | J33: 3 | K33: 25
A34: B-002 | B34: 7211004545 | C34: Nồi cơm điện Tefal Fuzzy Express | D34: SDA | E34: B | F34: 555 | G34: 2.5 | H34: =F34/G34 -> 222 | I34: 38.5 | J34: 3.8 | K34: 25
A35: B-003 | B35: 7211004640 | C35: Máy xay nấu đa năng Tefal Perfe | D35: SDA | E35: B | F35: 537 | G35: 2.5 | H35: =F35/G35 -> 214.8 | I35: 43.6 | J35: 2.5 | K35: 25
A36: B-004 | B36: 7211419352 | C36: Bình đun siêu tốc Tefal KI605830 | D36: SDA | E36: B | F36: 521 | G36: 2.5 | H36: =F36/G36 -> 208.4 | I36: 17.8 | J36: 2.4 | K36: 25
A37: B-005 | B37: 7211004596 | C37: Nồi cơm điện tửTefal Easy Rice P | D37: SDA | E37: B | F37: 509 | G37: 2.5 | H37: =F37/G37 -> 203.6 | I37: 48.5 | J37: 2.4 | K37: 25
A38: B-006 | B38: 2100122707 | C38: Chảo chiên sâu lồng Tefal So Che | D38: CW | E38: B | F38: 487 | G38: 2.5 | H38: =F38/G38 -> 194.8 | I38: 11.7 | J38: 3 | K38: 25
A39: B-007 | B39: 7211419468 | C39: Bình đun siêu tốc Tefal Colour K | D39: SDA | E39: B | F39: 460 | G39: 2.5 | H39: =F39/G39 -> 184 | I39: 11.8 | J39: 2.7 | K39: 25
A40: B-008 | B40: 2100122708 | C40: Chảo chiên Tefal So Chef 21cm | D40: CW | E40: B | F40: 437 | G40: 2.5 | H40: =F40/G40 -> 174.8 | I40: 7 | J40: 3.2 | K40: 25
A41: B-009 | B41: 4200008262 | C41: Quạt sàn TEFAL TB Silence Plus V | D41: Fan | E41: B | F41: 403 | G41: 2.5 | H41: =F41/G41 -> 161.2 | I41: 90.9 | J41: 5.1 | K41: 25
A42: B-010 | B42: 7211419432 | C42: Bình đun siêu tốc Tefal Colour K | D42: SDA | E42: B | F42: 357 | G42: 2.5 | H42: =F42/G42 -> 142.8 | I42: 13.2 | J42: 2.4 | K42: 25
A43: B-011 | B43: 2100122710 | C43: Chảo chiên Tefal So Chef 28cm | D43: CW | E43: B | F43: 354 | G43: 2.5 | H43: =F43/G43 -> 141.6 | I43: 20.4 | J43: 3.7 | K43: 25
A44: B-012 | B44: 1830008176 | C44: Bàn ủi hơi nước đứng Tefal IXEO | D44: SDA | E44: B | F44: 332 | G44: 2.5 | H44: =F44/G44 -> 132.8 | I44: 117.3 | J44: 2.5 | K44: 25
... A66: B-034 | B66: 4200009010 | C66: Quạt lửng BCN ASIAVINA - VY55889 | D66: Fan | E66: B | F66: 50 | G66: 2.5 | H66: =F66/G66 -> 20 | I66: 34.4 | J66: 34 | K66: 25
A67: B-035 | B67: 4200009621 | E67: B | F67: 48 | G67: 2.5 | H67: =F67/G67 -> 19.2 | I67: 102.6 | J67: 27.2 | K67: 25
A68: B-036 | B68: 4200008734 | C68: Quạt lửng ASIAVINA VY358792 - 55 | D68: Fan | E68: B | F68: 38 | G68: 2.5 | H68: =F68/G68 -> 15.2 | I68: 34.7 | J68: 27.3 | K68: 25
A69: B-037 | B69: 4200008735 | C69: Quạt lửng ASIAVINA VY358192 - 55 | D69: Fan | E69: B | F69: 37 | G69: 2.5 | H69: =F69/G69 -> 14.8 | I69: 34.7 | J69: 21.8 | K69: 25
A70: B-038 | B70: 4200008695 | C70: Quạt treo BCN ASIAVINA VY557990 | D70: Fan | E70: B | F70: 36 | G70: 2.5 | H70: =F70/G70 -> 14.4 | I70: 31.2 | J70: 61.2 | K70: 25
A71: B-039 | B71: 4200009294 | C71: Quạt đứng ASIAVINA Turbo X - VY6 | D71: CW | E71: B | F71: 1 | G71: 2.5 | H71: =F71/G71 -> 0.4 | I71: 46.8 | J71: 921 | K71: 25
A72: C-001 | B72: 7211004924 | C72: Nồi cơm điện tử cao tần Tefal RK | D72: SDA | E72: C | F72: 365 | G72: 2 | H72: =F72/G72 -> 182.5 | I72: 49.8 | J72: 2 | K72: 47.5
A73: C-002 | B73: 7211419286 | C73: Nồi chiên không dầu Tefal EasyFr | D73: SDA | E73: C | F73: 214 | G73: 2 | H73: =F73/G73 -> 107 | I73: 63.7 | J73: 3.1 | K73: 47.5
A74: C-003 | B74: 8010000653 | C74: Máy ép trái cây ZE420D38 | D74: SDA | E74: C | F74: 214 | G74: 2 | H74: =F74/G74 -> 107 | I74: 26.8 | J74: 2 | K74: 47.5
A75: C-004 | B75: 1830009015 | C75: Bàn ủi hơi nước đứng Tefal IT347 | D75: SDA | E75: C | F75: 198 | G75: 2 | H75: =F75/G75 -> 99 | I75: 74.2 | J75: 1.5 | K75: 47.5
A76: C-005 | B76: 2100118819 | C76: Chảo chiên Tefal Primary 26cm | D76: CW | E76: C | F76: 186 | G76: 2 | H76: =F76/G76 -> 93 | I76: 9.8 | J76: 2.9 | K76: 47.5
...

Sheet Q3.1 Heatmap (U-shape)
A1: Q3.1 - U-SHAPED WAREHOUSE HEATMAP
A2: Receiving + packing on the same front side. Zone A (red, highest pick density) hugs packing at 8 m; B mid; C wraps the back/outer ring at 47.5 m. Travel -35.4% vs random.

Sheet Q3.2 Pick & Pack
A1: Q3.2 - OMNI-CHANNEL PICK-AND-PACK PROCESS
A2: Unified process for B2B (pallet/total picking) and B2C (batch + zone routing), with shared-stock conflict logic linked to the 2.2 inventory pooling strategy.
A4: A. TWO PICK MODELS
A5: Channel | B5: Order profile | C5: Pick model | D5: Mechanics | E5: Pack
A6: B2B | B6: Large volume, few SKUs | C6: Pallet / Total Picking | D6: One picker fulfils whole pallets or large CTN qty per order in a single pass. Sources Zone A pick-face + Zone C bulk. | E6: Stage whole pallets; minimal re-sort.
A7: B2C / E-com | B7: Small qty, many SKUs, many concurrent orders | C7: Batch Picking + Zone Routing | D7: Group many small orders into one pick wave; pickers route by zone; items consolidated downstream. | E7: Sort the wave back to individual orders at packing.
A9: B. SHARED-SKU CONFLICT — ALLOCATION & ESCALATION RULES
A10: Scenario: the same SKU is ordered simultaneously by a B2B client and a B2C customer. Stock is held in ONE shared pool (per 2.2 pooling), not physically split.
A11: Rule | B11: Condition | C11: Action
A12: Check | B12: Same SKU, both channels, concurrent | C12: Evaluate on-hand vs (B2B + B2C) demand.
A13: Sufficient | B13: On-hand >= B2B + B2C | C13: Allocate to both from shared pool; no rationing.
A14: R1 | B14: Short stock | C14: Commit to the confirmed B2B PO first (contractual, penalty risk).
A15: R2 | B15: Short stock | C15: Hold the B2C safety buffer so the storefront does not show stockout.
A16: R3 | B16: Short + B2C SLA-critical (2-4h) | C16: Split: B2C SLA order gets partial now, backorder remainder.
A17: R4 | B17: Below reorder point | C17: Trigger emergency replenishment / inter-warehouse transfer.
A20: C. DECISION FLOWCHART
